Workbook
Name AmenTabla: Listas!$AJ$5:$AK$141
Name AmenTipo: Listas!$AJ$5:$AJ$141
Name LstActivo: Listas!$AH$5:$AH$238
Name LstCargo: Listas!$C$5:$C$14
Name LstEntorno: Listas!$E$5:$E$8
Name LstEstado: Listas!$G$5:$G$8
Name LstProceso: Listas!$B$5:$B$9
Name LstProcesoTodos: Listas!$AD$5:$AD$10
Name LstProveedor: Listas!$D$5:$D$18
Name LstSiNo: Listas!$F$5:$F$7
Name LstSubtipoTodos: Listas!$AG$5:$AG$142
Name LstTipo: Listas!$I$5:$I$14
Name LstTipoTodos: Listas!$AF$5:$AF$15
Name LstTratamiento: Listas!$H$5:$H$8
Name MgActId: '1. Matriz de Activos'!$B$6:$B$239
Name MgAmenClave: 'Amenazas MAGERIT'!$V$6:$V$62
Name MgAmenCod: 'Amenazas MAGERIT'!$B$6:$B$62
Name MgAmenCtrl: 'Amenazas MAGERIT'!$S$6:$S$62
Name MgAmenDegC: 'Amenazas MAGERIT'!$Q$6:$Q$62
Name MgAmenDegD: 'Amenazas MAGERIT'!$O$6:$O$62
Name MgAmenDegI: 'Amenazas MAGERIT'!$P$6:$P$62
Name MgAmenFrec: 'Amenazas MAGERIT'!$R$6:$R$62
Name MgAmenGrupo: 'Amenazas MAGERIT'!$D$6:$D$62
Name MgAmenNombre: 'Amenazas MAGERIT'!$C$6:$C$62
Name MgDeg: 'Escalas MAGERIT'!$B$20:$C$25
Name MgDegEt: 'Escalas MAGERIT'!$B$20:$B$25
Name MgFrec: 'Escalas MAGERIT'!$B$30:$C$34
Name MgFrecEt: 'Escalas MAGERIT'!$B$30:$B$34
Name MgMad: 'Escalas MAGERIT'!$B$40:$C$45
Name MgMadEt: 'Escalas MAGERIT'!$B$40:$B$45
Name MgNombre: '1. Matriz de Activos'!$C$6:$C$239
Name MgProceso: '1. Matriz de Activos'!$G$6:$G$239
Name MgSubtipo: '1. Matriz de Activos'!$F$6:$F$239
Name MgTipo: '1. Matriz de Activos'!$E$6:$E$239
Name MgValor: 'Escalas MAGERIT'!$B$6:$C$11
Name MgValorAct: '1. Matriz de Activos'!$T$6:$T$239
Name MgValorEt: 'Escalas MAGERIT'!$B$6:$B$11
Name RankProc: 'Amenazas MAGERIT'!$AN$6:$AN$62
Name SUB_AUX: Listas!$Q$5:$Q$16
Name SUB_COM: Listas!$O$5:$O$16
Name SUB_D: Listas!$J$5:$J$15
Name SUB_HW: Listas!$N$5:$N$26
Name SUB_K: Listas!$K$5:$K$18
Name SUB_L: Listas!$R$5:$R$14
Name SUB_Media: Listas!$P$5:$P$19
Name SUB_P: Listas!$S$5:$S$14
Name SUB_S: Listas!$L$5:$L$18
Name SUB_SW: Listas!$M$5:$M$21
Name TotProc: 'Amenazas MAGERIT'!$AO$6:$AO$62
Name LstMadurez: Listas!$AM$5:$AM$10
Name LstAplica: Listas!$AN$5:$AN$6
Name LstCapacidad: Listas!$AO$5:$AO$19
Name CtrlCod: '4. Controles y Madurez'!$B$6:$B$98
Name CtrlDom: '4. Controles y Madurez'!$D$6:$D$98
Name CtrlCap: '4. Controles y Madurez'!$E$6:$E$98
Name CtrlAplica: '4. Controles y Madurez'!$F$6:$F$98
Name CtrlBase: '4. Controles y Madurez'!$G$6:$G$98
Name CtrlActual: '4. Controles y Madurez'!$H$6:$H$98
Name CtrlObjetivo: '4. Controles y Madurez'!$I$6:$I$98
Name CtrlEfic: '4. Controles y Madurez'!$J$6:$J$98

Sheet Dashboard
B1: TABLERO DE RIESGOS — MAGERIT v3.0
B2: Todo responde al proceso elegido en la celda amarilla.
B3: Código de color: | C3: Amarillo = Campo de entrada — se selecciona de una lista | E3: Lila = Calculado automáticamente — no escribir encima | G3: Gris = Dato de la norma MAGERIT — no modificar
B5: Proceso o Área | C5: (Todos los procesos)
B7: INDICADORES DEL PROCESO SELECCIONADO
B8: Activos del proceso | C8: =IF($C$5="(Todos los procesos)",COUNTA('1. Matriz de Activos'!$B$6:$B$239),COUNTIF('1. Matriz de Activos'!$G$6:$G$239,$C$5))
B9: Activos valorados (valor 4 o más) | C9: =IF($C$5="(Todos los procesos)",COUNTIF(MgValorAct,">=4"),COUNTIFS('1. Matriz de Activos'!$G$6:$G$239,$C$5,MgValorAct,">=4"))
B10: Riesgos evaluados | C10: =IF($C$5="(Todos los procesos)",COUNTA('2. Valoración '!$B$6:$B$2261),COUNTIF('2. Valoración '!$E$6:$E$2261,$C$5))
B11: Riesgos Alto o Crítico (inherente) | C11: =IF($C$5="(Todos los procesos)",COUNTIF('2. Valoración '!$Z$6:$Z$2261,"Alto")+COUNTIF('2. Valoración '!$Z$6:$Z$2261,"Crítico"),COUNTIFS('2. Valoración '!$E$6:$E$2261,$C$5,'2. Valoración '!$Z$6:$Z$2261,"Alto")+COUNTIFS('2. Valoración '!$E$6:$E$2261,$C$5,'2. Valoración '!$Z$6:$Z$2261,"Crítico"))
B12: Riesgos Alto o Crítico (residual) | C12: =IF($C$5="(Todos los procesos)",COUNTIF('2. Valoración '!$AG$6:$AG$2261,"Alto")+COUNTIF('2. Valoración '!$AG$6:$AG$2261,"Crítico"),COUNTIFS('2. Valoración '!$E$6:$E$2261,$C$5,'2. Valoración '!$AG$6:$AG$2261,"Alto")+COUNTIFS('2. Valoración '!$E$6:$E$2261,$C$5,'2. Valoración '!$AG$6:$AG$2261,"Crítico"))
B14: ACTIVOS POR TIPO MAGERIT | F14: RIESGO INHERENTE FRENTE A RESIDUAL
B15: Tipo de activo | C15: Activos | D15: Valorados | F15: Nivel de riesgo | G15: Inherente | H15: Residual
B16: [D] Datos / Información | C16: =IF($C$5="(Todos los procesos)",COUNTIF(MgTipo,$B16),COUNTIFS('1. Matriz de Activos'!$G$6:$G$239,$C$5,MgTipo,$B16)) | D16: =IF($C$5="(Todos los procesos)",COUNTIFS(MgTipo,$B16,MgValorAct,">=4"),COUNTIFS('1. Matriz de Activos'!$G$6:$G$239,$C$5,MgTipo,$B16,MgValorAct,">=4")) | F16: Crítico | G16: =IF($C$5="(Todos los procesos)",COUNTIF('2. Valoración '!$Z$6:$Z$2261,$F16),COUNTIFS('2. Valoración '!$E$6:$E$2261,$C$5,'2. Valoración '!$Z$6:$Z$2261,$F16)) | H16: =IF($C$5="(Todos los procesos)",COUNTIF('2. Valoración '!$AG$6:$AG$2261,$F16),COUNTIFS('2. Valoración '!$E$6:$E$2261,$C$5,'2. Valoración '!$AG$6:$AG$2261,$F16))
B17: [K] Claves criptográficas | C17: =IF($C$5="(Todos los procesos)",COUNTIF(MgTipo,$B17),COUNTIFS('1. Matriz de Activos'!$G$6:$G$239,$C$5,MgTipo,$B17)) | D17: =IF($C$5="(Todos los procesos)",COUNTIFS(MgTipo,$B17,MgValorAct,">=4"),COUNTIFS('1. Matriz de Activos'!$G$6:$G$239,$C$5,MgTipo,$B17,MgValorAct,">=4")) | F17: Alto | G17: =IF($C$5="(Todos los procesos)",COUNTIF('2. Valoración '!$Z$6:$Z$2261,$F17),COUNTIFS('2. Valoración '!$E$6:$E$2261,$C$5,'2. Valoración '!$Z$6:$Z$2261,$F17)) | H17: =IF($C$5="(Todos los procesos)",COUNTIF('2. Valoración '!$AG$6:$AG$2261,$F17),COUNTIFS('2. Valoración '!$E$6:$E$2261,$C$5,'2. Valoración '!$AG$6:$AG$2261,$F17))
B18: [S] Servicios | C18: =IF($C$5="(Todos los procesos)",COUNTIF(MgTipo,$B18),COUNTIFS('1. Matriz de Activos'!$G$6:$G$239,$C$5,MgTipo,$B18)) | D18: =IF($C$5="(Todos los procesos)",COUNTIFS(MgTipo,$B18,MgValorAct,">=4"),COUNTIFS('1. Matriz de Activos'!$G$6:$G$239,$C$5,MgTipo,$B18,MgValorAct,">=4")) | F18: Medio | G18: =IF($C$5="(Todos los procesos)",COUNTIF('2. Valoración '!$Z$6:$Z$2261,$F18),COUNTIFS('2. Valoración '!$E$6:$E$2261,$C$5,'2. Valoración '!$Z$6:$Z$2261,$F18)) | H18: =IF($C$5="(Todos los procesos)",COUNTIF('2. Valoración '!$AG$6:$AG$2261,$F18),COUNTIFS('2. Valoración '!$E$6:$E$2261,$C$5,'2. Valoración '!$AG$6:$AG$2261,$F18))
B19: [SW] Aplicaciones (software) | C19: =IF($C$5="(Todos los procesos)",COUNTIF(MgTipo,$B19),COUNTIFS('1. Matriz de Activos'!$G$6:$G$239,$C$5,MgTipo,$B19)) | D19: =IF($C$5="(Todos los procesos)",COUNTIFS(MgTipo,$B19,MgValorAct,">=4"),COUNTIFS('1. Matriz de Activos'!$G$6:$G$239,$C$5,MgTipo,$B19,MgValorAct,">=4")) | F19: Bajo | G19: =IF($C$5="(Todos los procesos)",COUNTIF('2. Valoración '!$Z$6:$Z$2261,$F19),COUNTIFS('2. Valoración '!$E$6:$E$2261,$C$5,'2. Valoración '!$Z$6:$Z$2261,$F19)) | H19: =IF($C$5="(Todos los procesos)",COUNTIF('2. Valoración '!$AG$6:$AG$2261,$F19),COUNTIFS('2. Valoración '!$E$6:$E$2261,$C$5,'2. Valoración '!$AG$6:$AG$2261,$F19))
B20: [HW] Equipamiento informático (hardware) | C20: =IF($C$5="(Todos los procesos)",COUNTIF(MgTipo,$B20),COUNTIFS('1. Matriz de Activos'!$G$6:$G$239,$C$5,MgTipo,$B20)) | D20: =IF($C$5="(Todos los procesos)",COUNTIFS(MgTipo,$B20,MgValorAct,">=4"),COUNTIFS('1. Matriz de Activos'!$G$6:$G$239,$C$5,MgTipo,$B20,MgValorAct,">=4"))
B21: [COM] Redes de comunicaciones | C21: =IF($C$5="(Todos los procesos)",COUNTIF(MgTipo,$B21),COUNTIFS('1. Matriz de Activos'!$G$6:$G$239,$C$5,MgTipo,$B21)) | D21: =IF($C$5="(Todos los procesos)",COUNTIFS(MgTipo,$B21,MgValorAct,">=4"),COUNTIFS('1. Matriz de Activos'!$G$6:$G$239,$C$5,MgTipo,$B21,MgValorAct,">=4"))
B22: [Media] Soportes de información | C22: =IF($C$5="(Todos los procesos)",COUNTIF(MgTipo,$B22),COUNTIFS('1. Matriz de Activos'!$G$6:$G$239,$C$5,MgTipo,$B22)) | D22: =IF($C$5="(Todos los procesos)",COUNTIFS(MgTipo,$B22,MgValorAct,">=4"),COUNTIFS('1. Matriz de Activos'!$G$6:$G$239,$C$5,MgTipo,$B22,MgValorAct,">=4"))
B23: [AUX] Equipamiento auxiliar | C23: =IF($C$5="(Todos los procesos)",COUNTIF(MgTipo,$B23),COUNTIFS('1. Matriz de Activos'!$G$6:$G$239,$C$5,MgTipo,$B23)) | D23: =IF($C$5="(Todos los procesos)",COUNTIFS(MgTipo,$B23,MgValorAct,">=4"),COUNTIFS('1. Matriz de Activos'!$G$6:$G$239,$C$5,MgTipo,$B23,MgValorAct,">=4"))
B24: [L] Instalaciones | C24: =IF($C$5="(Todos los procesos)",COUNTIF(MgTipo,$B24),COUNTIFS('1. Matriz de Activos'!$G$6:$G$239,$C$5,MgTipo,$B24)) | D24: =IF($C$5="(Todos los procesos)",COUNTIFS(MgTipo,$B24,MgValorAct,">=4"),COUNTIFS('1. Matriz de Activos'!$G$6:$G$239,$C$5,MgTipo,$B24,MgValorAct,">=4"))
B25: [P] Personal | C25: =IF($C$5="(Todos los procesos)",COUNTIF(MgTipo,$B25),COUNTIFS('1. Matriz de Activos'!$G$6:$G$239,$C$5,MgTipo,$B25)) | D25: =IF($C$5="(Todos los procesos)",COUNTIFS(MgTipo,$B25,MgValorAct,">=4"),COUNTIFS('1. Matriz de Activos'!$G$6:$G$239,$C$5,MgTipo,$B25,MgValorAct,">=4"))
B28: RIESGOS POR GRUPO DE AMENAZA | F28: MADUREZ DE LOS CONTROLES REGISTRADA
B29: Grupo MAGERIT | C29: Riesgos | D29: Alto o Crítico | F29: Nivel de madurez | G29: Riesgos
B30: [A] Ataques intencionados | C30: =IF($C$5="(Todos los procesos)",COUNTIF('2. Valoración '!$J$6:$J$2261,$B30),COUNTIFS('2. Valoración '!$E$6:$E$2261,$C$5,'2. Valoración '!$J$6:$J$2261,$B30)) | D30: =IF($C$5="(Todos los procesos)",COUNTIFS('2. Valoración '!$J$6:$J$2261,$B30,'2. Valoración '!$Z$6:$Z$2261,"Alto")+COUNTIFS('2. Valoración '!$J$6:$J$2261,$B30,'2. Valoración '!$Z$6:$Z$2261,"Crítico"),COUNTIFS('2. Valoración '!$E$6:$E$2261,$C$5,'2. Valoración '!$J$6:$J$2261,$B30,'2. Valoración '!$Z$6:$Z$2261,"Alto")+COUNTIFS('2. Valoración '!$E$6:$E$2261,$C$5,'2. Valoración '!$J$6:$J$2261,$B30,'2. Valoración '!$Z$6:$Z$2261,"Crítico")) | F30: L0 — Inexistente | G30: =IF($C$5="(Todos los procesos)",COUNTIF('2. Valoración '!$AC$6:$AC$2261,$F30),COUNTIFS('2. Valoración '!$E$6:$E$2261,$C$5,'2. Valoración '!$AC$6:$AC$2261,$F30))
B31: [E] Errores y fallos no intencionados | C31: =IF($C$5="(Todos los procesos)",COUNTIF('2. Valoración '!$J$6:$J$2261,$B31),COUNTIFS('2. Valoración '!$E$6:$E$2261,$C$5,'2. Valoración '!$J$6:$J$2261,$B31)) | D31: =IF($C$5="(Todos los procesos)",COUNTIFS('2. Valoración '!$J$6:$J$2261,$B31,'2. Valoración '!$Z$6:$Z$2261,"Alto")+COUNTIFS('2. Valoración '!$J$6:$J$2261,$B31,'2. Valoración '!$Z$6:$Z$2261,"Crítico"),COUNTIFS('2. Valoración '!$E$6:$E$2261,$C$5,'2. Valoración '!$J$6:$J$2261,$B31,'2. Valoración '!$Z$6:$Z$2261,"Alto")+COUNTIFS('2. Valoración '!$E$6:$E$2261,$C$5,'2. Valoración '!$J$6:$J$2261,$B31,'2. Valoración '!$Z$6:$Z$2261,"Crítico")) | F31: L1 — Inicial / ad hoc | G31: =IF($C$5="(Todos los procesos)",COUNTIF('2. Valoración '!$AC$6:$AC$2261,$F31),COUNTIFS('2. Valoración '!$E$6:$E$2261,$C$5,'2. Valoración '!$AC$6:$AC$2261,$F31))
B32: [I] De origen industrial | C32: =IF($C$5="(Todos los procesos)",COUNTIF('2. Valoración '!$J$6:$J$2261,$B32),COUNTIFS('2. Valoración '!$E$6:$E$2261,$C$5,'2. Valoración '!$J$6:$J$2261,$B32)) | D32: =IF($C$5="(Todos los procesos)",COUNTIFS('2. Valoración '!$J$6:$J$2261,$B32,'2. Valoración '!$Z$6:$Z$2261,"Alto")+COUNTIFS('2. Valoración '!$J$6:$J$2261,$B32,'2. Valoración '!$Z$6:$Z$2261,"Crítico"),COUNTIFS('2. Valoración '!$E$6:$E$2261,$C$5,'2. Valoración '!$J$6:$J$2261,$B32,'2. Valoración '!$Z$6:$Z$2261,"Alto")+COUNTIFS('2. Valoración '!$E$6:$E$2261,$C$5,'2. Valoración '!$J$6:$J$2261,$B32,'2. Valoración '!$Z$6:$Z$2261,"Crítico")) | F32: L2 — Reproducible pero intuitivo | G32: =IF($C$5="(Todos los procesos)",COUNTIF('2. Valoración '!$AC$6:$AC$2261,$F32),COUNTIFS('2. Valoración '!$E$6:$E$2261,$C$5,'2. Valoración '!$AC$6:$AC$2261,$F32))
B33: [N] Desastres naturales | C33: =IF($C$5="(Todos los procesos)",COUNTIF('2. Valoración '!$J$6:$J$2261,$B33),COUNTIFS('2. Valoración '!$E$6:$E$2261,$C$5,'2. Valoración '!$J$6:$J$2261,$B33)) | D33: =IF($C$5="(Todos los procesos)",COUNTIFS('2. Valoración '!$J$6:$J$2261,$B33,'2. Valoración '!$Z$6:$Z$2261,"Alto")+COUNTIFS('2. Valoración '!$J$6:$J$2261,$B33,'2. Valoración '!$Z$6:$Z$2261,"Crítico"),COUNTIFS('2. Valoración '!$E$6:$E$2261,$C$5,'2. Valoración '!$J$6:$J$2261,$B33,'2. Valoración '!$Z$6:$Z$2261,"Alto")+COUNTIFS('2. Valoración '!$E$6:$E$2261,$C$5,'2. Valoración '!$J$6:$J$2261,$B33,'2. Valoración '!$Z$6:$Z$2261,"Crítico")) | F33: L3 — Proceso definido | G33: =IF($C$5="(Todos los procesos)",COUNTIF('2. Valoración '!$AC$6:$AC$2261,$F33),COUNTIFS('2. Valoración '!$E$6:$E$2261,$C$5,'2. Valoración '!$AC$6:$AC$2261,$F33))
F34: L4 — Gestionado y medible | G34: =IF($C$5="(Todos los procesos)",COUNTIF('2. Valoración '!$AC$6:$AC$2261,$F34),COUNTIFS('2. Valoración '!$E$6:$E$2261,$C$5,'2. Valoración '!$AC$6:$AC$2261,$F34))
F35: L5 — Optimizado | G35: =IF($C$5="(Todos los procesos)",COUNTIF('2. Valoración '!$AC$6:$AC$2261,$F35),COUNTIFS('2. Valoración '!$E$6:$E$2261,$C$5,'2. Valoración '!$AC$6:$AC$2261,$F35))
B38: AMENAZAS CON MÁS RIESGOS ALTO O CRÍTICO EN EL PROCESO SELECCIONADO
B39: Código | C39: Amenaza | D39: Riesgos Alto o Crítico | E39: Riesgos totales
B40: =IFERROR(INDEX('Amenazas MAGERIT'!$B$6:$B$62,MATCH(LARGE(RankProc,1),RankProc,0)),"") | C40: =IFERROR(INDEX('Amenazas MAGERIT'!$C$6:$C$62,MATCH(LARGE(RankProc,1),RankProc,0)),"") | D40: =IFERROR(INT(LARGE(RankProc,1)),"") | E40: =IFERROR(INDEX(TotProc,MATCH(LARGE(RankProc,1),RankProc,0)),"")
B41: =IFERROR(INDEX('Amenazas MAGERIT'!$B$6:$B$62,MATCH(LARGE(RankProc,2),RankProc,0)),"") | C41: =IFERROR(INDEX('Amenazas MAGERIT'!$C$6:$C$62,MATCH(LARGE(RankProc,2),RankProc,0)),"") | D41: =IFERROR(INT(LARGE(RankProc,2)),"") | E41: =IFERROR(INDEX(TotProc,MATCH(LARGE(RankProc,2),RankProc,0)),"")
B42: =IFERROR(INDEX('Amenazas MAGERIT'!$B$6:$B$62,MATCH(LARGE(RankProc,3),RankProc,0)),"") | C42: =IFERROR(INDEX('Amenazas MAGERIT'!$C$6:$C$62,MATCH(LARGE(RankProc,3),RankProc,0)),"") | D42: =IFERROR(INT(LARGE(RankProc,3)),"") | E42: =IFERROR(INDEX(TotProc,MATCH(LARGE(RankProc,3),RankProc,0)),"")
B43: =IFERROR(INDEX('Amenazas MAGERIT'!$B$6:$B$62,MATCH(LARGE(RankProc,4),RankProc,0)),"") | C43: =IFERROR(INDEX('Amenazas MAGERIT'!$C$6:$C$62,MATCH(LARGE(RankProc,4),RankProc,0)),"") | D43: =IFERROR(INT(LARGE(RankProc,4)),"") | E43: =IFERROR(INDEX(TotProc,MATCH(LARGE(RankProc,4),RankProc,0)),"")
B44: =IFERROR(INDEX('Amenazas MAGERIT'!$B$6:$B$62,MATCH(LARGE(RankProc,5),RankProc,0)),"") | C44: =IFERROR(INDEX('Amenazas MAGERIT'!$C$6:$C$62,MATCH(LARGE(RankProc,5),RankProc,0)),"") | D44: =IFERROR(INT(LARGE(RankProc,5)),"") | E44: =IFERROR(INDEX(TotProc,MATCH(LARGE(RankProc,5),RankProc,0)),"")
B45: =IFERROR(INDEX('Amenazas MAGERIT'!$B$6:$B$62,MATCH(LARGE(RankProc,6),RankProc,0)),"") | C45: =IFERROR(INDEX('Amenazas MAGERIT'!$C$6:$C$62,MATCH(LARGE(RankProc,6),RankProc,0)),"") | D45: =IFERROR(INT(LARGE(RankProc,6)),"") | E45: =IFERROR(INDEX(TotProc,MATCH(LARGE(RankProc,6),RankProc,0)),"")
B46: =IFERROR(INDEX('Amenazas MAGERIT'!$B$6:$B$62,MATCH(LARGE(RankProc,7),RankProc,0)),"") | C46: =IFERROR(INDEX('Amenazas MAGERIT'!$C$6:$C$62,MATCH(LARGE(RankProc,7),RankProc,0)),"") | D46: =IFERROR(INT(LARGE(RankProc,7)),"") | E46: =IFERROR(INDEX(TotProc,MATCH(LARGE(RankProc,7),RankProc,0)),"")
B47: =IFERROR(INDEX('Amenazas MAGERIT'!$B$6:$B$62,MATCH(LARGE(RankProc,8),RankProc,0)),"") | C47: =IFERROR(INDEX('Amenazas MAGERIT'!$C$6:$C$62,MATCH(LARGE(RankProc,8),RankProc,0)),"") | D47: =IFERROR(INT(LARGE(RankProc,8)),"") | E47: =IFERROR(INDEX(TotProc,MATCH(LARGE(RankProc,8),RankProc,0)),"")
...

Sheet Guía de uso
B1: ANÁLISIS DE RIESGOS SEGÚN MAGERIT v3.0 — GUÍA DE USO
B2: Cuántico adopta MAGERIT de manera integral. Esta hoja explica para qué sirve cada hoja y en qué orden se trabaja.
B3: Código de color: | C3: Amarillo = Campo de entrada — se selecciona de una lista | E3: Lila = Calculado automáticamente — no escribir encima | G3: Gris = Dato de la norma MAGERIT — no modificar
B5: QUÉ CONTIENE ESTE ARCHIVO
B6: Hoja | C6: Para qué sirve | D6: Su papel
B7: Dashboard | C7: Indicadores de riesgo filtrables por proceso. Es la vista de arranque y la que se lleva al Comité. | D7: Ver
B8: Matriz de Activos MAGERIT | C8: El inventario: 234 activos clasificados por tipo MAGERIT y valorados en las tres dimensiones. | D8: Diligenciar
B9: Agregar Activo | C9: Muestra qué activos faltan por valorar y genera, listas para copiar, las filas que hay que crear en la Valoración. | D9: Usar
B10: Valoración MAGERIT | C10: La evaluación de riesgos: impacto por dimensión, riesgo anual y riesgo residual según la madurez de los controles. | D10: Diligenciar
B11: Matrices de Riesgo | C11: Los mapas de calor inherente y residual, con el recuento por nivel. | D11: Ver
B12: Amenazas MAGERIT | C12: Las 57 amenazas con los tipos de activo y dimensiones que la norma les asigna. Aquí se ajusta la degradación y la frecuencia. | D12: Diligenciar
B13: Tipos de Activo MAGERIT | C13: Los 10 tipos y 137 subtipos oficiales, con la cantidad de activos que hay en cada uno. | D13: Referencia
B14: Escalas MAGERIT | C14: Todas las listas y reglas de cálculo. Cambiar un valor aquí recalcula la valoración entera. | D14: Parámetros
B15: Listas | C15: Alimenta los desplegables. No se modifica sin autorización. | D15: Apoyo
B16: Comparativa de Modelos | C16: Registro de la comparación entre el modelo anterior y MAGERIT. Sustenta la decisión ante el auditor. | D16: Evidencia
B18: EN QUÉ ORDEN SE TRABAJA
B19: Paso | C19: Qué se hace
B20: 1 · Mantener el inventario | C20: En «Matriz de Activos MAGERIT» se registra cada activo nuevo, se clasifica con los desplegables de tipo y subtipo, se completan sus atributos y se valora en Disponibilidad, Integridad y Confidencialidad. El valor del activo se calcula solo.
B21: 2 · Ver qué falta por valorar | C21: En «Agregar Activo» se filtra por proceso, tipo y subtipo. La columna «Situación» dice si a cada activo le faltan filas en la Valoración y cuántas.
B22: 3 · Crear las filas de riesgo | C22: En el bloque 3 de esa misma hoja se elige el activo, se filtra «¿Aplica?» por «Sí» y se copian las filas a «Valoración MAGERIT».
B23: 4 · Ajustar degradación y frecuencia | C23: Se hace en «Amenazas MAGERIT», no fila por fila: lo que se cambie ahí se propaga a todos los riesgos de esa amenaza.
B24: 5 · Registrar la madurez de los controles | C24: En «Valoración MAGERIT», columna amarilla. Es lo único que separa el riesgo residual del inherente.
B25: 6 · Revisar y decidir | C25: El Dashboard y las Matrices de Riesgo dan la lectura por proceso y el mapa de calor para llevar al Comité.
B27: RESUMEN NUMÉRICO
B28: Activos inventariados | C28: Tipos MAGERIT en uso | D28: Amenazas del catálogo | E28: Activos valorados | F28: Riesgos evaluados
B29: 234 | C29: 7 | D29: 57 | E29: 122 | F29: 2256
B31: Fuentes: MAGERIT v3.0, Libro I «Método» y Libro II «Catálogo de Elementos» (Ministerio de Hacienda y Administraciones Públicas de España, octubre de 2012), e ISO/IEC 27001:2022 Anexo A.
B33: Novedad de esta versión: la eficacia que reduce el riesgo residual ya no se escribe riesgo por riesgo. Sale de la madurez real de los controles registrada en la hoja «4. Controles y Madurez»: cada amenaza toma la eficacia media de los controles que la mitigan. La columna de madurez en la hoja de Valoración queda como sobrescritura manual para casos puntuales.

Sheet 1. Matriz de Activos
B1: MATRIZ DE ACTIVOS — ESTRUCTURA MAGERIT v3.0
B2: Inventario reorganizado por tipo MAGERIT y valorado en Disponibilidad, Integridad y Confidencialidad (escala 0 a 5).
B3: Código de color: | C3: Amarillo = Campo de entrada — se selecciona de una lista | E3: Lila = Calculado automáticamente — no escribir encima | G3: Gris = Dato de la norma MAGERIT — no modificar
B5: Código | C5: Nombre del activo | D5: Descripción | E5: Tipo | F5: Subtipo | G5: Proceso o Área | H5: Responsable (custodio) | I5: Propietario del activo | J5: Ubicación | K5: Entorno | L5: ¿Contiene datos de cliente? | M5: ¿Contiene datos personales (Ley 1581)? | N5: ¿Está expuesto a Internet? | O5: Proveedor o subencargado | P5: Depende del activo superior | Q5: Valor en Disponibilidad | R5: Valor en Integridad | S5: Valor en Confidencialidad | T5: Valor del activo (0 a 5) | U5: Nivel del activo
B6: TEC-008 | C6: Backups-Diarios | E6: [D] Datos / Información | F6: [backup] Copias de respaldo | G6: Gestión Tecnológica | H6: Gestión Tecnológica | J6: Nube | K6: No aplica | L6: Por definir | M6: Por definir | N6: Por definir | O6: Amazon Web Services | Q6: 3 — Medio | R6: 4 — Alto | S6: 4 — Alto | T6: =MAX(IFERROR(VLOOKUP(Q6,MgValor,2,0),0),IFERROR(VLOOKUP(R6,MgValor,2,0),0),IFERROR(VLOOKUP(S6,MgValor,2,0),0)) | U6: =IFERROR(LOOKUP(T6,{0;1;2;3;4;5},{"Irrelevante";"Muy Bajo";"Bajo";"Medio";"Alto";"Muy Alto"}),"")
B7: GH-057 | C7: rpa-impoconsumo-releases | D7: Repositorio de releases (paquetes y versiones distribuibles) de la aplicación Impoconsumo ILC | E7: [D] Datos / Información | F7: [exe] Código ejecutable | G7: Gestión Tecnológica | H7: Jhon Tamayo | J7: Nube | K7: No aplica | L7: Por definir | M7: Por definir | N7: Por definir | Q7: 3 — Medio | R7: 4 — Alto | S7: 4 — Alto | T7: =MAX(IFERROR(VLOOKUP(Q7,MgValor,2,0),0),IFERROR(VLOOKUP(R7,MgValor,2,0),0),IFERROR(VLOOKUP(S7,MgValor,2,0),0)) | U7: =IFERROR(LOOKUP(T7,{0;1;2;3;4;5},{"Irrelevante";"Muy Bajo";"Bajo";"Medio";"Alto";"Muy Alto"}),"")
B8: TAL-11 | C8: Actas de descargos / procesos disciplinarios | D8: Registro de llamados de atención y procesos disciplinarios | E8: [D] Datos / Información | F8: [files] Archivos | G8: Talento Humano | H8: Finance and Administrative Manager | J8: Nube | K8: No aplica | L8: Por definir | M8: Por definir | N8: Por definir | Q8: 3 — Medio | R8: 4 — Alto | S8: 4 — Alto | T8: =MAX(IFERROR(VLOOKUP(Q8,MgValor,2,0),0),IFERROR(VLOOKUP(R8,MgValor,2,0),0),IFERROR(VLOOKUP(S8,MgValor,2,0),0)) | U8: =IFERROR(LOOKUP(T8,{0;1;2;3;4;5},{"Irrelevante";"Muy Bajo";"Bajo";"Medio";"Alto";"Muy Alto"}),"")
B9: COM-16 | C9: Base de datos de prospectos de MinTrace | D9: Repositorio que contiene la información comercial y de contacto de empresas y personas potencialmente interesadas en los productos y servicios de MinTrace. | E9: [D] Datos / Información | F9: [files] Archivos | G9: Gestión Comercial | H9: Chief Commercial Officer | J9: N.A. | K9: No aplica | L9: Sí | M9: Por definir | N9: Por definir | Q9: 3 — Medio | R9: 4 — Alto | S9: 4 — Alto | T9: =MAX(IFERROR(VLOOKUP(Q9,MgValor,2,0),0),IFERROR(VLOOKUP(R9,MgValor,2,0),0),IFERROR(VLOOKUP(S9,MgValor,2,0),0)) | U9: =IFERROR(LOOKUP(T9,{0;1;2;3;4;5},{"Irrelevante";"Muy Bajo";"Bajo";"Medio";"Alto";"Muy Alto"}),"")
B10: COM-21 | C10: Capacitaciones | D10: Repositorio que contiene los materiales de formación utilizados para entrenar a los nuevos integrantes del equipo comercial en el portafolio de soluciones de Cuantico, los procesos comerciales, las metodologías de venta, el uso de herramientas y demás lineamientos necesarios para el desarrollo de sus funciones. | E10: [D] Datos / Información | F10: [files] Archivos | G10: Gestión Comercial | H10: Chief Commercial Officer | J10: N.A. | K10: Desarrollo | L10: Por definir | M10: Por definir | N10: Por definir | Q10: 3 — Medio | R10: 4 — Alto | S10: 4 — Alto | T10: =MAX(IFERROR(VLOOKUP(Q10,MgValor,2,0),0),IFERROR(VLOOKUP(R10,MgValor,2,0),0),IFERROR(VLOOKUP(S10,MgValor,2,0),0)) | U10: =IFERROR(LOOKUP(T10,{0;1;2;3;4;5},{"Irrelevante";"Muy Bajo";"Bajo";"Medio";"Alto";"Muy Alto"}),"")
B11: TAL-13 | C11: Carpeta de desvinculación | D11: Renuncia/terminación, paz y salvo, liquidación, certificaciones | E11: [D] Datos / Información | F11: [files] Archivos | G11: Talento Humano | H11: Finance and Administrative Manager | J11: Nube | K11: No aplica | L11: Por definir | M11: Sí | N11: Por definir | Q11: 3 — Medio | R11: 4 — Alto | S11: 4 — Alto | T11: =MAX(IFERROR(VLOOKUP(Q11,MgValor,2,0),0),IFERROR(VLOOKUP(R11,MgValor,2,0),0),IFERROR(VLOOKUP(S11,MgValor,2,0),0)) | U11: =IFERROR(LOOKUP(T11,{0;1;2;3;4;5},{"Irrelevante";"Muy Bajo";"Bajo";"Medio";"Alto";"Muy Alto"}),"")
B12: TAL-12 | C12: Carpeta de ingreso de colaborador | D12: RUT, hoja de vida, cédula, EPS, AFP, fondo de cesantías, certificados | E12: [D] Datos / Información | F12: [files] Archivos | G12: Talento Humano | H12: Finance and Administrative Manager | J12: Nube | K12: No aplica | L12: Por definir | M12: Sí | N12: Por definir | Q12: 3 — Medio | R12: 4 — Alto | S12: 4 — Alto | T12: =MAX(IFERROR(VLOOKUP(Q12,MgValor,2,0),0),IFERROR(VLOOKUP(R12,MgValor,2,0),0),IFERROR(VLOOKUP(S12,MgValor,2,0),0)) | U12: =IFERROR(LOOKUP(T12,{0;1;2;3;4;5},{"Irrelevante";"Muy Bajo";"Bajo";"Medio";"Alto";"Muy Alto"}),"")
B13: FIN-06 | C13: Consolidado control financiero Egresos (FOR-FIN-03) | D13: Registro y control de egresos y pagos | E13: [D] Datos / Información | F13: [files] Archivos | G13: Gestión Financiera | H13: Finance and Administrative Manager | J13: Nube | K13: No aplica | L13: Por definir | M13: Por definir | N13: Por definir | Q13: 3 — Medio | R13: 4 — Alto | S13: 4 — Alto | T13: =MAX(IFERROR(VLOOKUP(Q13,MgValor,2,0),0),IFERROR(VLOOKUP(R13,MgValor,2,0),0),IFERROR(VLOOKUP(S13,MgValor,2,0),0)) | U13: =IFERROR(LOOKUP(T13,{0;1;2;3;4;5},{"Irrelevante";"Muy Bajo";"Bajo";"Medio";"Alto";"Muy Alto"}),"")
B14: FIN-07 | C14: Consolidado control financiero Ingresos (FOR-FIN-05) | D14: Registro y control de ingresos y facturación | E14: [D] Datos / Información | F14: [files] Archivos | G14: Gestión Financiera | H14: Finance and Administrative Manager | J14: Nube | K14: No aplica | L14: Por definir | M14: Por definir | N14: Por definir | Q14: 3 — Medio | R14: 4 — Alto | S14: 4 — Alto | T14: =MAX(IFERROR(VLOOKUP(Q14,MgValor,2,0),0),IFERROR(VLOOKUP(R14,MgValor,2,0),0),IFERROR(VLOOKUP(S14,MgValor,2,0),0)) | U14: =IFERROR(LOOKUP(T14,{0;1;2;3;4;5},{"Irrelevante";"Muy Bajo";"Bajo";"Medio";"Alto";"Muy Alto"}),"")
B15: LCO-08 | C15: Documentación de contratistas (hojas de vida, cédula, RUT, certificaciones) | D15: Documentos de identificación y soporte contractual de contratistas personas naturales | E15: [D] Datos / Información | F15: [files] Archivos | G15: Gestión Legal y Compras | H15: Chief Legal Officer | J15: Nube | K15: No aplica | L15: Por definir | M15: Sí | N15: Por definir | Q15: 3 — Medio | R15: 3 — Medio | S15: 4 — Alto | T15: =MAX(IFERROR(VLOOKUP(Q15,MgValor,2,0),0),IFERROR(VLOOKUP(R15,MgValor,2,0),0),IFERROR(VLOOKUP(S15,MgValor,2,0),0)) | U15: =IFERROR(LOOKUP(T15,{0;1;2;3;4;5},{"Irrelevante";"Muy Bajo";"Bajo";"Medio";"Alto";"Muy Alto"}),"")
B16: COM-18 | C16: Equipo de Trabajo | D16: Repositorio consolidado con la información de funcionarios y proveedores de Cuantico, organizada en el formato de hoja de vida corporativa. Se utiliza para validar perfiles, experiencia, formación y cumplimiento de requisitos en procesos de contratación y licitaciones. | E16: [D] Datos / Información | F16: [files] Archivos | G16: Gestión Comercial | H16: Chief Commercial Officer | J16: N.A. | K16: No aplica | L16: Por definir | M16: Sí | N16: Por definir | Q16: 3 — Medio | R16: 4 — Alto | S16: 4 — Alto | T16: =MAX(IFERROR(VLOOKUP(Q16,MgValor,2,0),0),IFERROR(VLOOKUP(R16,MgValor,2,0),0),IFERROR(VLOOKUP(S16,MgValor,2,0),0)) | U16: =IFERROR(LOOKUP(T16,{0;1;2;3;4;5},{"Irrelevante";"Muy Bajo";"Bajo";"Medio";"Alto";"Muy Alto"}),"")
B17: COM-19 | C17: Experiencia | D17: Repositorio que consolida las certificaciones de los clientes, contratos y proyectos en los que ha participado Cuantico, incluyendo las experiencias registradas en el RUP. Se utiliza para acreditar la trayectoria de la empresa y validar el cumplimiento de requisitos de experiencia en procesos de contratación y licitaciones. | E17: [D] Datos / Información | F17: [files] Archivos | G17: Gestión Comercial | H17: Chief Commercial Officer | J17: N.A. | K17: No aplica | L17: Sí | M17: Por definir | N17: Por definir | Q17: 3 — Medio | R17: 4 — Alto | S17: 4 — Alto | T17: =MAX(IFERROR(VLOOKUP(Q17,MgValor,2,0),0),IFERROR(VLOOKUP(R17,MgValor,2,0),0),IFERROR(VLOOKUP(S17,MgValor,2,0),0)) | U17: =IFERROR(LOOKUP(T17,{0;1;2;3;4;5},{"Irrelevante";"Muy Bajo";"Bajo";"Medio";"Alto";"Muy Alto"}),"")
B18: COM-05 | C18: Forecast (FOR-COM-01) | D18: Proyección y seguimiento de oportunidades y ventas | E18: [D] Datos / Información | F18: [files] Archivos | G18: Gestión Comercial | H18: Chief Commercial Officer | J18: Nube | K18: No aplica | L18: Por definir | M18: Por definir | N18: Por definir | Q18: 3 — Medio | R18: 4 — Alto | S18: 4 — Alto | T18: =MAX(IFERROR(VLOOKUP(Q18,MgValor,2,0),0),IFERROR(VLOOKUP(R18,MgValor,2,0),0),IFERROR(VLOOKUP(S18,MgValor,2,0),0)) | U18: =IFERROR(LOOKUP(T18,{0;1;2;3;4;5},{"Irrelevante";"Muy Bajo";"Bajo";"Medio";"Alto";"Muy Alto"}),"")
... B115: FIN-27 | C115: Facturación electrónica DIAN / RADIAN | D115: Emisión/recepción de facturas electrónicas vía Siigo | E115: [S] Servicios | F115: [ext] A usuarios externos bajo una relación contractual | G115: Gestión Financiera | H115: Gestión Tecnológica | J115: Nube | K115: Producción | L115: Por definir | M115: Por definir | N115: Por definir | Q115: 4 — Alto | R115: 4 — Alto | S115: 3 — Medio | T115: =MAX(IFERROR(VLOOKUP(Q115,MgValor,2,0),0),IFERROR(VLOOKUP(R115,MgValor,2,0),0),IFERROR(VLOOKUP(S115,MgValor,2,0),0)) | U115: =IFERROR(LOOKUP(T115,{0;1;2;3;4;5},{"Irrelevante";"Muy Bajo";"Bajo";"Medio";"Alto";"Muy Alto"}),"")
B116: TEC-014 | C116: Hosting-Web | E116: [S] Servicios | F116: [ext] A usuarios externos bajo una relación contractual | G116: Gestión Tecnológica | H116: Gestión Tecnológica | J116: Nube | K116: Producción | L116: Por definir | M116: Por definir | N116: Por definir | Q116: 4 — Alto | R116: 3 — Medio | S116: 2 — Bajo | T116: =MAX(IFERROR(VLOOKUP(Q116,MgValor,2,0),0),IFERROR(VLOOKUP(R116,MgValor,2,0),0),IFERROR(VLOOKUP(S116,MgValor,2,0),0)) | U116: =IFERROR(LOOKUP(T116,{0;1;2;3;4;5},{"Irrelevante";"Muy Bajo";"Bajo";"Medio";"Alto";"Muy Alto"}),"")
B117: MS-02 | C117: Microsoft 365 Business Standard | D117: Suite de ofimática y colaboración (Office, Teams, OneDrive) | E117: [S] Servicios | F117: [ext] A usuarios externos bajo una relación contractual | G117: Gestión Tecnológica | H117: Gestión Tecnológica | J117: Nube | K117: Producción | L117: Por definir | M117: Por definir | N117: Por definir | Q117: 4 — Alto | R117: 4 — Alto | S117: 4 — Alto | T117: =MAX(IFERROR(VLOOKUP(Q117,MgValor,2,0),0),IFERROR(VLOOKUP(R117,MgValor,2,0),0),IFERROR(VLOOKUP(S117,MgValor,2,0),0)) | U117: =IFERROR(LOOKUP(T117,{0;1;2;3;4;5},{"Irrelevante";"Muy Bajo";"Bajo";"Medio";"Alto";"Muy Alto"}),"")
B118: FIN-28 | C118: Plataforma de seguridad social (PILA) | D118: Liquidación y pago de aportes de seguridad social | E118: [S] Servicios | F118: [ext] A usuarios externos bajo una relación contractual | G118: Gestión Financiera | H118: Finance and Administrative Manager | J118: Nube | K118: Producción | L118: Por definir | M118: Por definir | N118: Por definir | Q118: 4 — Alto | R118: 4 — Alto | S118: 4 — Alto | T118: =MAX(IFERROR(VLOOKUP(Q118,MgValor,2,0),0),IFERROR(VLOOKUP(R118,MgValor,2,0),0),IFERROR(VLOOKUP(S118,MgValor,2,0),0)) | U118: =IFERROR(LOOKUP(T118,{0;1;2;3;4;5},{"Irrelevante";"Muy Bajo";"Bajo";"Medio";"Alto";"Muy Alto"}),"")
B119: FIN-23 | C119: Portal bancario (Innovaciencia) | D119: Portal bancario de la entidad Innovaciencia | E119: [S] Servicios | F119: [ext] A usuarios externos bajo una relación contractual | G119: Gestión Financiera | H119: Finance and Administrative Manager | J119: Nube | K119: Producción | L119: Por definir | M119: Por definir | N119: Por definir | Q119: 4 — Alto | R119: 4 — Alto | S119: 4 — Alto | T119: =MAX(IFERROR(VLOOKUP(Q119,MgValor,2,0),0),IFERROR(VLOOKUP(R119,MgValor,2,0),0),IFERROR(VLOOKUP(S119,MgValor,2,0),0)) | U119: =IFERROR(LOOKUP(T119,{0;1;2;3;4;5},{"Irrelevante";"Muy Bajo";"Bajo";"Medio";"Alto";"Muy Alto"}),"")
B120: FIN-22 | C120: Portal bancario Colpatria (Cuantico Corporation) | D120: Portal de tesorería: pagos a proveedores, impuestos y nómina | E120: [S] Servicios | F120: [ext] A usuarios externos bajo una relación contractual | G120: Gestión Financiera | H120: Finance and Administrative Manager | J120: Nube | K120: Producción | L120: Por definir | M120: Sí | N120: Por definir | Q120: 4 — Alto | R120: 4 — Alto | S120: 4 — Alto | T120: =MAX(IFERROR(VLOOKUP(Q120,MgValor,2,0),0),IFERROR(VLOOKUP(R120,MgValor,2,0),0),IFERROR(VLOOKUP(S120,MgValor,2,0),0)) | U120: =IFERROR(LOOKUP(T120,{0;1;2;3;4;5},{"Irrelevante";"Muy Bajo";"Bajo";"Medio";"Alto";"Muy Alto"}),"")
B121: FIN-24 | C121: Portal(es) bancario(s) — GovTech / otras entidades | D121: Portales bancarios de otras entidades del grupo | E121: [S] Servicios | F121: [ext] A usuarios externos bajo una relación contractual | G121: Gestión Financiera | H121: Finance and Administrative Manager | J121: Nube | K121: Producción | L121: Por definir | M121: Por definir | N121: Por definir | Q121: 4 — Alto | R121: 4 — Alto | S121: 4 — Alto | T121: =MAX(IFERROR(VLOOKUP(Q121,MgValor,2,0),0),IFERROR(VLOOKUP(R121,MgValor,2,0),0),IFERROR(VLOOKUP(S121,MgValor,2,0),0)) | U121: =IFERROR(LOOKUP(T121,{0;1;2;3;4;5},{"Irrelevante";"Muy Bajo";"Bajo";"Medio";"Alto";"Muy Alto"}),"")
B122: MS-03 | C122: Power BI Premium Per User Add-On | D122: Complemento de analítica y visualización de datos | E122: [S] Servicios | F122: [ext] A usuarios externos bajo una relación contractual | G122: Gestión Tecnológica | H122: Gestión Tecnológica | J122: Nube | K122: Producción | L122: Por definir | M122: Por definir | N122: Por definir | Q122: 3 — Medio | R122: 3 — Medio | S122: 4 — Alto | T122: =MAX(IFERROR(VLOOKUP(Q122,MgValor,2,0),0),IFERROR(VLOOKUP(R122,MgValor,2,0),0),IFERROR(VLOOKUP(S122,MgValor,2,0),0)) | U122: =IFERROR(LOOKUP(T122,{0;1;2;3;4;5},{"Irrelevante";"Muy Bajo";"Bajo";"Medio";"Alto";"Muy Alto"}),"")
B123: MS-04 | C123: Power BI Pro | D123: Licencia de analítica y publicación de tableros | E123: [S] Servicios | F123: [ext] A usuarios externos bajo una relación contractual | G123: Gestión Tecnológica | H123: Gestión Tecnológica | J123: Nube | K123: Producción | L123: Por definir | M123: Por definir | N123: Por definir | Q123: 3 — Medio | R123: 3 — Medio | S123: 4 — Alto | T123: =MAX(IFERROR(VLOOKUP(Q123,MgValor,2,0),0),IFERROR(VLOOKUP(R123,MgValor,2,0),0),IFERROR(VLOOKUP(S123,MgValor,2,0),0)) | U123: =IFERROR(LOOKUP(T123,{0;1;2;3;4;5},{"Irrelevante";"Muy Bajo";"Bajo";"Medio";"Alto";"Muy Alto"}),"")
B124: SW-01 | C124: Zohodesk | D124: Plataforma SaaS de mesa de ayuda y gestión de tickets de soporte | E124: [S] Servicios | F124: [ext] A usuarios externos bajo una relación contractual | G124: Gestión Tecnológica | H124: Gestión Tecnológica | J124: Nube | K124: Producción | L124: Por definir | M124: Por definir | N124: Por definir | Q124: 3 — Medio | R124: 3 — Medio | S124: 4 — Alto | T124: =MAX(IFERROR(VLOOKUP(Q124,MgValor,2,0),0),IFERROR(VLOOKUP(R124,MgValor,2,0),0),IFERROR(VLOOKUP(S124,MgValor,2,0),0)) | U124: =IFERROR(LOOKUP(T124,{0;1;2;3;4;5},{"Irrelevante";"Muy Bajo";"Bajo";"Medio";"Alto";"Muy Alto"}),"")
B125: FIN-26 | C125: Firma electrónica DIAN (por entidad) | D125: Certificados de firma para declaraciones y trámites DIAN | E125: [S] Servicios | F125: [int] Interno (a usuarios de la organización) | G125: Gestión Financiera | J125: Nube | K125: Producción | L125: Por definir | M125: Por definir | N125: Por definir | Q125: 4 — Alto | R125: 4 — Alto | S125: 4 — Alto | T125: =MAX(IFERROR(VLOOKUP(Q125,MgValor,2,0),0),IFERROR(VLOOKUP(R125,MgValor,2,0),0),IFERROR(VLOOKUP(S125,MgValor,2,0),0)) | U125: =IFERROR(LOOKUP(T125,{0;1;2;3;4;5},{"Irrelevante";"Muy Bajo";"Bajo";"Medio";"Alto";"Muy Alto"}),"")
B126: TEC-029 | C126: grafana-with-postgresql-stt1myj34… | E126: [S] Servicios | F126: [int] Interno (a usuarios de la organización) | G126: Gestión Tecnológica | H126: Gestión Tecnológica | J126: Nube | K126: Producción | L126: Por definir | M126: Por definir | N126: Por definir | Q126: 2 — Bajo | R126: 2 — Bajo | S126: 2 — Bajo | T126: =MAX(IFERROR(VLOOKUP(Q126,MgValor,2,0),0),IFERROR(VLOOKUP(R126,MgValor,2,0),0),IFERROR(VLOOKUP(S126,MgValor,2,0),0)) | U126: =IFERROR(LOOKUP(T126,{0;1;2;3;4;5},{"Irrelevante";"Muy Bajo";"Bajo";"Medio";"Alto";"Muy Alto"}),"")
B127: TEC-037 | C127: n8n-with-postgres-and-worker-o48w… | E127: [S] Servicios | F127: [int] Interno (a usuarios de la organización) | G127: Gestión Tecnológica | H127: Gestión Tecnológica | J127: Nube | K127: Producción | L127: Por definir | M127: Por definir | N127: Por definir | Q127: 3 — Medio | R127: 3 — Medio | S127: 3 — Medio | T127: =MAX(IFERROR(VLOOKUP(Q127,MgValor,2,0),0),IFERROR(VLOOKUP(R127,MgValor,2,0),0),IFERROR(VLOOKUP(S127,MgValor,2,0),0)) | U127: =IFERROR(LOOKUP(T127,{0;1;2;3;4;5},{"Irrelevante";"Muy Bajo";"Bajo";"Medio";"Alto";"Muy Alto"}),"")
B128: TEC-039 | C128: plane-q08s8ccksok44w8k4cs0ow0g | E128: [S] Servicios | F128: [int] Interno (a usuarios de la organización) | G128: Gestión Tecnológica | H128: Gestión Tecnológica | J128: Nube | K128: Producción | L128: Por definir | M128: Por definir | N128: Por definir | Q128: 3 — Medio | R128: 3 — Medio | S128: 3 — Medio | T128: =MAX(IFERROR(VLOOKUP(Q128,MgValor,2,0),0),IFERROR(VLOOKUP(R128,MgValor,2,0),0),IFERROR(VLOOKUP(S128,MgValor,2,0),0)) | U128: =IFERROR(LOOKUP(T128,{0;1;2;3;4;5},{"Irrelevante";"Muy Bajo";"Bajo";"Medio";"Alto";"Muy Alto"}),"")
B129: TEC-041 | C129: service-ucsoggg4w400swcskwsookkw | E129: [S] Servicios | F129: [int] Interno (a usuarios de la organización) | G129: Gestión Tecnológica | H129: Gestión Tecnológica | J129: Nube | K129: Producción | L129: Por definir | M129: Por definir | N129: Por definir | Q129: 3 — Medio | R129: 3 — Medio | S129: 3 — Medio | T129: =MAX(IFERROR(VLOOKUP(Q129,MgValor,2,0),0),IFERROR(VLOOKUP(R129,MgValor,2,0),0),IFERROR(VLOOKUP(S129,MgValor,2,0),0)) | U129: =IFERROR(LOOKUP(T129,{0;1;2;3;4;5},{"Irrelevante";"Muy Bajo";"Bajo";"Medio";"Alto";"Muy Alto"}),"")
B130: TEC-070 | C130: umami-vf22xvxrc2a08lc8nl6vmtyt | E130: [S] Servicios | F130: [int] Interno (a usuarios de la organización) | G130: Gestión Tecnológica | H130: Gestión Tecnológica | J130: Nube | K130: Producción | L130: Por definir | M130: Por definir | N130: Por definir | Q130: 3 — Medio | R130: 3 — Medio | S130: 3 — Medio | T130: =MAX(IFERROR(VLOOKUP(Q130,MgValor,2,0),0),IFERROR(VLOOKUP(R130,MgValor,2,0),0),IFERROR(VLOOKUP(S130,MgValor,2,0),0)) | U130: =IFERROR(LOOKUP(T130,{0;1;2;3;4;5},{"Irrelevante";"Muy Bajo";"Bajo";"Medio";"Alto";"Muy Alto"}),"")
B131: TEC-002 | C131: BD-Postgres-Main | E131: [SW] Aplicaciones (software) | F131: [dbms] Sistema de gestión de bases de datos | G131: Gestión Tecnológica | H131: Gestión Tecnológica | J131: Nube | K131: Producción | L131: Por definir | M131: Por definir | N131: Por definir | Q131: 4 — Alto | R131: 4 — Alto | S131: 4 — Alto | T131: =MAX(IFERROR(VLOOKUP(Q131,MgValor,2,0),0),IFERROR(VLOOKUP(R131,MgValor,2,0),0),IFERROR(VLOOKUP(S131,MgValor,2,0),0)) | U131: =IFERROR(LOOKUP(T131,{0;1;2;3;4;5},{"Irrelevante";"Muy Bajo";"Bajo";"Medio";"Alto";"Muy Alto"}),"")
B132: TEC-001 | C132: API-Gateway | E132: [SW] Aplicaciones (software) | F132: [prp] Desarrollo propio (in house) | G132: Gestión Tecnológica | H132: Gestión Tecnológica | J132: Nube | K132: Producción | L132: Por definir | M132: Por definir | N132: Por definir | Q132: 4 — Alto | R132: 4 — Alto | S132: 3 — Medio | T132: =MAX(IFERROR(VLOOKUP(Q132,MgValor,2,0),0),IFERROR(VLOOKUP(R132,MgValor,2,0),0),IFERROR(VLOOKUP(S132,MgValor,2,0),0)) | U132: =IFERROR(LOOKUP(T132,{0;1;2;3;4;5},{"Irrelevante";"Muy Bajo";"Bajo";"Medio";"Alto";"Muy Alto"}),"")
B133: COM-14 | C133: CRM comercial de MinTrace. | D133: Herramienta utilizada para registrar y gestionar prospectos, clientes, oportunidades comerciales, seguimientos, propuestas, negociaciones y cierres de venta de MinTrace. | E133: [SW] Aplicaciones (software) | F133: [prp] Desarrollo propio (in house) | G133: Gestión Comercial | H133: Chief Commercial Officer | J133: N.A. | K133: Producción | L133: Sí | M133: Por definir | N133: Por definir | Q133: 3 — Medio | R133: 4 — Alto | S133: 4 — Alto | T133: =MAX(IFERROR(VLOOKUP(Q133,MgValor,2,0),0),IFERROR(VLOOKUP(R133,MgValor,2,0),0),IFERROR(VLOOKUP(S133,MgValor,2,0),0)) | U133: =IFERROR(LOOKUP(T133,{0;1;2;3;4;5},{"Irrelevante";"Muy Bajo";"Bajo";"Medio";"Alto";"Muy Alto"}),"")
B134: COM-15 | C134: Cuantico Verify. | D134: Aplicación utilizada para realizar procesos de validación, debida diligencia, consulta en listas restrictivas y verificación de información de clientes, proveedores o terceros. | E134: [SW] Aplicaciones (software) | F134: [prp] Desarrollo propio (in house) | G134: Gestión Comercial | H134: Chief Commercial Officer | J134: N.A. | K134: Producción | L134: Sí | M134: Por definir | N134: Por definir | Q134: 3 — Medio | R134: 4 — Alto | S134: 4 — Alto | T134: =MAX(IFERROR(VLOOKUP(Q134,MgValor,2,0),0),IFERROR(VLOOKUP(R134,MgValor,2,0),0),IFERROR(VLOOKUP(S134,MgValor,2,0),0)) | U134: =IFERROR(LOOKUP(T134,{0;1;2;3;4;5},{"Irrelevante";"Muy Bajo";"Bajo";"Medio";"Alto";"Muy Alto"}),"")
B135: TEC-024 | C135: evolution-api-uehp2jesgnh7cfzl6sy… | E135: [SW] Aplicaciones (software) | F135: [prp] Desarrollo propio (in house) | G135: Gestión Tecnológica | H135: Gestión Tecnológica | J135: Nube | K135: Producción | L135: Por definir | M135: Por definir | N135: Por definir | Q135: 3 — Medio | R135: 3 — Medio | S135: 3 — Medio | T135: =MAX(IFERROR(VLOOKUP(Q135,MgValor,2,0),0),IFERROR(VLOOKUP(R135,MgValor,2,0),0),IFERROR(VLOOKUP(S135,MgValor,2,0),0)) | U135: =IFERROR(LOOKUP(T135,{0;1;2;3;4;5},{"Irrelevante";"Muy Bajo";"Bajo";"Medio";"Alto";"Muy Alto"}),"")
B136: TEC-025 | C136: gateway-admin-dev | E136: [SW] Aplicaciones (software) | F136: [prp] Desarrollo propio (in house) | G136: Gestión Tecnológica | H136: Gestión Tecnológica | J136: Nube | K136: Producción | L136: Por definir | M136: Por definir | N136: Por definir | Q136: 2 — Bajo | R136: 2 — Bajo | S136: 2 — Bajo | T136: =MAX(IFERROR(VLOOKUP(Q136,MgValor,2,0),0),IFERROR(VLOOKUP(R136,MgValor,2,0),0),IFERROR(VLOOKUP(S136,MgValor,2,0),0)) | U136: =IFERROR(LOOKUP(T136,{0;1;2;3;4;5},{"Irrelevante";"Muy Bajo";"Bajo";"Medio";"Alto";"Muy Alto"}),"")
B137: TEC-026 | C137: gateway-admin-staging | E137: [SW] Aplicaciones (software) | F137: [prp] Desarrollo propio (in house) | G137: Gestión Tecnológica | H137: Gestión Tecnológica | J137: Nube | K137: Staging | L137: Por definir | M137: Por definir | N137: Por definir | Q137: 2 — Bajo | R137: 2 — Bajo | S137: 2 — Bajo | T137: =MAX(IFERROR(VLOOKUP(Q137,MgValor,2,0),0),IFERROR(VLOOKUP(R137,MgValor,2,0),0),IFERROR(VLOOKUP(S137,MgValor,2,0),0)) | U137: =IFERROR(LOOKUP(T137,{0;1;2;3;4;5},{"Irrelevante";"Muy Bajo";"Bajo";"Medio";"Alto";"Muy Alto"}),"")
...

Sheet 1.1 Agregar Activo
B1: AGREGAR ACTIVO — QUÉ FALTA POR VALORAR Y QUÉ FILAS HAY QUE CREAR
B2: Arriba: filtre por proceso, tipo y subtipo para ver qué activos faltan por valorar. Abajo: elija un activo y obtenga, listas para copiar, las filas que le corresponden en la hoja de Valoración.
B3: Código de color: | C3: Amarillo = Campo de entrada — se selecciona de una lista | E3: Lila = Calculado automáticamente — no escribir encima | G3: Gris = Dato de la norma MAGERIT — no modificar
B5: 1 · FILTRE PARA VER QUÉ ACTIVOS FALTAN
B6: Proceso o Área | C6: Gestión Tecnológica | G6: Activos que cumplen el filtro | I6: =COUNTIF($B$11:$B$244,"Sí")
B7: Tipo MAGERIT | C7: [HW] Equipamiento informático (hardware) | G7: De ellos, requieren valoración (valor 4 o más) | I7: =COUNTIFS($B$11:$B$244,"Sí",$I$11:$I$244,"Sí")
B8: Subtipo MAGERIT | C8: (Todos los subtipos)
B9: 2 · ACTIVOS Y ESTADO DE SU VALORACIÓN (filtre la columna «Cumple el filtro» por «Sí»)
B10: Cumple el filtro | C10: Código | D10: Nombre del activo | E10: Proceso o Área | F10: Tipo MAGERIT | G10: Subtipo MAGERIT | H10: Valor del activo | I10: ¿Requiere valoración? | J10: Filas que le corresponden | K10: Filas ya registradas | L10: Situación
B11: =IF(AND(OR($C$6="(Todos los procesos)",$C$6='1. Matriz de Activos'!$G$6),OR($C$7="(Todos los tipos)",$C$7='1. Matriz de Activos'!$E$6),OR($C$8="(Todos los subtipos)",$C$8='1. Matriz de Activos'!$F$6)),"Sí","No") | C11: ='1. Matriz de Activos'!$B$6 | D11: ='1. Matriz de Activos'!$C$6 | E11: ='1. Matriz de Activos'!$G$6 | F11: ='1. Matriz de Activos'!$E$6 | G11: ='1. Matriz de Activos'!$F$6 | H11: ='1. Matriz de Activos'!$T$6 | I11: =IF($H11>=4,"Sí","No") | J11: =IF($H11>=4,IFERROR(VLOOKUP($G11,AmenTabla,2,0),0),0) | K11: =COUNTIF('2. Valoración '!$C$6:$C$2261,$C11) | L11: =IF($I11="No","No requiere valoración",IF($K11=0,"FALTA POR COMPLETO — agregar "&$J11&" filas",IF($K11<$J11,"INCOMPLETO — faltan "&($J11-$K11)&" filas",IF($K11>$J11,"REVISAR — hay filas de más","Completo"))))
B12: =IF(AND(OR($C$6="(Todos los procesos)",$C$6='1. Matriz de Activos'!$G$7),OR($C$7="(Todos los tipos)",$C$7='1. Matriz de Activos'!$E$7),OR($C$8="(Todos los subtipos)",$C$8='1. Matriz de Activos'!$F$7)),"Sí","No") | C12: ='1. Matriz de Activos'!$B$7 | D12: ='1. Matriz de Activos'!$C$7 | E12: ='1. Matriz de Activos'!$G$7 | F12: ='1. Matriz de Activos'!$E$7 | G12: ='1. Matriz de Activos'!$F$7 | H12: ='1. Matriz de Activos'!$T$7 | I12: =IF($H12>=4,"Sí","No") | J12: =IF($H12>=4,IFERROR(VLOOKUP($G12,AmenTabla,2,0),0),0) | K12: =COUNTIF('2. Valoración '!$C$6:$C$2261,$C12) | L12: =IF($I12="No","No requiere valoración",IF($K12=0,"FALTA POR COMPLETO — agregar "&$J12&" filas",IF($K12<$J12,"INCOMPLETO — faltan "&($J12-$K12)&" filas",IF($K12>$J12,"REVISAR — hay filas de más","Completo"))))
B13: =IF(AND(OR($C$6="(Todos los procesos)",$C$6='1. Matriz de Activos'!$G$8),OR($C$7="(Todos los tipos)",$C$7='1. Matriz de Activos'!$E$8),OR($C$8="(Todos los subtipos)",$C$8='1. Matriz de Activos'!$F$8)),"Sí","No") | C13: ='1. Matriz de Activos'!$B$8 | D13: ='1. Matriz de Activos'!$C$8 | E13: ='1. Matriz de Activos'!$G$8 | F13: ='1. Matriz de Activos'!$E$8 | G13: ='1. Matriz de Activos'!$F$8 | H13: ='1. Matriz de Activos'!$T$8 | I13: =IF($H13>=4,"Sí","No") | J13: =IF($H13>=4,IFERROR(VLOOKUP($G13,AmenTabla,2,0),0),0) | K13: =COUNTIF('2. Valoración '!$C$6:$C$2261,$C13) | L13: =IF($I13="No","No requiere valoración",IF($K13=0,"FALTA POR COMPLETO — agregar "&$J13&" filas",IF($K13<$J13,"INCOMPLETO — faltan "&($J13-$K13)&" filas",IF($K13>$J13,"REVISAR — hay filas de más","Completo"))))
B14: =IF(AND(OR($C$6="(Todos los procesos)",$C$6='1. Matriz de Activos'!$G$9),OR($C$7="(Todos los tipos)",$C$7='1. Matriz de Activos'!$E$9),OR($C$8="(Todos los subtipos)",$C$8='1. Matriz de Activos'!$F$9)),"Sí","No") | C14: ='1. Matriz de Activos'!$B$9 | D14: ='1. Matriz de Activos'!$C$9 | E14: ='1. Matriz de Activos'!$G$9 | F14: ='1. Matriz de Activos'!$E$9 | G14: ='1. Matriz de Activos'!$F$9 | H14: ='1. Matriz de Activos'!$T$9 | I14: =IF($H14>=4,"Sí","No") | J14: =IF($H14>=4,IFERROR(VLOOKUP($G14,AmenTabla,2,0),0),0) | K14: =COUNTIF('2. Valoración '!$C$6:$C$2261,$C14) | L14: =IF($I14="No","No requiere valoración",IF($K14=0,"FALTA POR COMPLETO — agregar "&$J14&" filas",IF($K14<$J14,"INCOMPLETO — faltan "&($J14-$K14)&" filas",IF($K14>$J14,"REVISAR — hay filas de más","Completo"))))
B15: =IF(AND(OR($C$6="(Todos los procesos)",$C$6='1. Matriz de Activos'!$G$10),OR($C$7="(Todos los tipos)",$C$7='1. Matriz de Activos'!$E$10),OR($C$8="(Todos los subtipos)",$C$8='1. Matriz de Activos'!$F$10)),"Sí","No") | C15: ='1. Matriz de Activos'!$B$10 | D15: ='1. Matriz de Activos'!$C$10 | E15: ='1. Matriz de Activos'!$G$10 | F15: ='1. Matriz de Activos'!$E$10 | G15: ='1. Matriz de Activos'!$F$10 | H15: ='1. Matriz de Activos'!$T$10 | I15: =IF($H15>=4,"Sí","No") | J15: =IF($H15>=4,IFERROR(VLOOKUP($G15,AmenTabla,2,0),0),0) | K15: =COUNTIF('2. Valoración '!$C$6:$C$2261,$C15) | L15: =IF($I15="No","No requiere valoración",IF($K15=0,"FALTA POR COMPLETO — agregar "&$J15&" filas",IF($K15<$J15,"INCOMPLETO — faltan "&($J15-$K15)&" filas",IF($K15>$J15,"REVISAR — hay filas de más","Completo"))))
B16: =IF(AND(OR($C$6="(Todos los procesos)",$C$6='1. Matriz de Activos'!$G$11),OR($C$7="(Todos los tipos)",$C$7='1. Matriz de Activos'!$E$11),OR($C$8="(Todos los subtipos)",$C$8='1. Matriz de Activos'!$F$11)),"Sí","No") | C16: ='1. Matriz de Activos'!$B$11 | D16: ='1. Matriz de Activos'!$C$11 | E16: ='1. Matriz de Activos'!$G$11 | F16: ='1. Matriz de Activos'!$E$11 | G16: ='1. Matriz de Activos'!$F$11 | H16: ='1. Matriz de Activos'!$T$11 | I16: =IF($H16>=4,"Sí","No") | J16: =IF($H16>=4,IFERROR(VLOOKUP($G16,AmenTabla,2,0),0),0) | K16: =COUNTIF('2. Valoración '!$C$6:$C$2261,$C16) | L16: =IF($I16="No","No requiere valoración",IF($K16=0,"FALTA POR COMPLETO — agregar "&$J16&" filas",IF($K16<$J16,"INCOMPLETO — faltan "&($J16-$K16)&" filas",IF($K16>$J16,"REVISAR — hay filas de más","Completo"))))
B17: =IF(AND(OR($C$6="(Todos los procesos)",$C$6='1. Matriz de Activos'!$G$12),OR($C$7="(Todos los tipos)",$C$7='1. Matriz de Activos'!$E$12),OR($C$8="(Todos los subtipos)",$C$8='1. Matriz de Activos'!$F$12)),"Sí","No") | C17: ='1. Matriz de Activos'!$B$12 | D17: ='1. Matriz de Activos'!$C$12 | E17: ='1. Matriz de Activos'!$G$12 | F17: ='1. Matriz de Activos'!$E$12 | G17: ='1. Matriz de Activos'!$F$12 | H17: ='1. Matriz de Activos'!$T$12 | I17: =IF($H17>=4,"Sí","No") | J17: =IF($H17>=4,IFERROR(VLOOKUP($G17,AmenTabla,2,0),0),0) | K17: =COUNTIF('2. Valoración '!$C$6:$C$2261,$C17) | L17: =IF($I17="No","No requiere valoración",IF($K17=0,"FALTA POR COMPLETO — agregar "&$J17&" filas",IF($K17<$J17,"INCOMPLETO — faltan "&($J17-$K17)&" filas",IF($K17>$J17,"REVISAR — hay filas de más","Completo"))))
B18: =IF(AND(OR($C$6="(Todos los procesos)",$C$6='1. Matriz de Activos'!$G$13),OR($C$7="(Todos los tipos)",$C$7='1. Matriz de Activos'!$E$13),OR($C$8="(Todos los subtipos)",$C$8='1. Matriz de Activos'!$F$13)),"Sí","No") | C18: ='1. Matriz de Activos'!$B$13 | D18: ='1. Matriz de Activos'!$C$13 | E18: ='1. Matriz de Activos'!$G$13 | F18: ='1. Matriz de Activos'!$E$13 | G18: ='1. Matriz de Activos'!$F$13 | H18: ='1. Matriz de Activos'!$T$13 | I18: =IF($H18>=4,"Sí","No") | J18: =IF($H18>=4,IFERROR(VLOOKUP($G18,AmenTabla,2,0),0),0) | K18: =COUNTIF('2. Valoración '!$C$6:$C$2261,$C18) | L18: =IF($I18="No","No requiere valoración",IF($K18=0,"FALTA POR COMPLETO — agregar "&$J18&" filas",IF($K18<$J18,"INCOMPLETO — faltan "&($J18-$K18)&" filas",IF($K18>$J18,"REVISAR — hay filas de más","Completo"))))
B19: =IF(AND(OR($C$6="(Todos los procesos)",$C$6='1. Matriz de Activos'!$G$14),OR($C$7="(Todos los tipos)",$C$7='1. Matriz de Activos'!$E$14),OR($C$8="(Todos los subtipos)",$C$8='1. Matriz de Activos'!$F$14)),"Sí","No") | C19: ='1. Matriz de Activos'!$B$14 | D19: ='1. Matriz de Activos'!$C$14 | E19: ='1. Matriz de Activos'!$G$14 | F19: ='1. Matriz de Activos'!$E$14 | G19: ='1. Matriz de Activos'!$F$14 | H19: ='1. Matriz de Activos'!$T$14 | I19: =IF($H19>=4,"Sí","No") | J19: =IF($H19>=4,IFERROR(VLOOKUP($G19,AmenTabla,2,0),0),0) | K19: =COUNTIF('2. Valoración '!$C$6:$C$2261,$C19) | L19: =IF($I19="No","No requiere valoración",IF($K19=0,"FALTA POR COMPLETO — agregar "&$J19&" filas",IF($K19<$J19,"INCOMPLETO — faltan "&($J19-$K19)&" filas",IF($K19>$J19,"REVISAR — hay filas de más","Completo"))))
B20: =IF(AND(OR($C$6="(Todos los procesos)",$C$6='1. Matriz de Activos'!$G$15),OR($C$7="(Todos los tipos)",$C$7='1. Matriz de Activos'!$E$15),OR($C$8="(Todos los subtipos)",$C$8='1. Matriz de Activos'!$F$15)),"Sí","No") | C20: ='1. Matriz de Activos'!$B$15 | D20: ='1. Matriz de Activos'!$C$15 | E20: ='1. Matriz de Activos'!$G$15 | F20: ='1. Matriz de Activos'!$E$15 | G20: ='1. Matriz de Activos'!$F$15 | H20: ='1. Matriz de Activos'!$T$15 | I20: =IF($H20>=4,"Sí","No") | J20: =IF($H20>=4,IFERROR(VLOOKUP($G20,AmenTabla,2,0),0),0) | K20: =COUNTIF('2. Valoración '!$C$6:$C$2261,$C20) | L20: =IF($I20="No","No requiere valoración",IF($K20=0,"FALTA POR COMPLETO — agregar "&$J20&" filas",IF($K20<$J20,"INCOMPLETO — faltan "&($J20-$K20)&" filas",IF($K20>$J20,"REVISAR — hay filas de más","Completo"))))
B21: =IF(AND(OR($C$6="(Todos los procesos)",$C$6='1. Matriz de Activos'!$G$16),OR($C$7="(Todos los tipos)",$C$7='1. Matriz de Activos'!$E$16),OR($C$8="(Todos los subtipos)",$C$8='1. Matriz de Activos'!$F$16)),"Sí","No") | C21: ='1. Matriz de Activos'!$B$16 | D21: ='1. Matriz de Activos'!$C$16 | E21: ='1. Matriz de Activos'!$G$16 | F21: ='1. Matriz de Activos'!$E$16 | G21: ='1. Matriz de Activos'!$F$16 | H21: ='1. Matriz de Activos'!$T$16 | I21: =IF($H21>=4,"Sí","No") | J21: =IF($H21>=4,IFERROR(VLOOKUP($G21,AmenTabla,2,0),0),0) | K21: =COUNTIF('2. Valoración '!$C$6:$C$2261,$C21) | L21: =IF($I21="No","No requiere valoración",IF($K21=0,"FALTA POR COMPLETO — agregar "&$J21&" filas",IF($K21<$J21,"INCOMPLETO — faltan "&($J21-$K21)&" filas",IF($K21>$J21,"REVISAR — hay filas de más","Completo"))))
B22: =IF(AND(OR($C$6="(Todos los procesos)",$C$6='1. Matriz de Activos'!$G$17),OR($C$7="(Todos los tipos)",$C$7='1. Matriz de Activos'!$E$17),OR($C$8="(Todos los subtipos)",$C$8='1. Matriz de Activos'!$F$17)),"Sí","No") | C22: ='1. Matriz de Activos'!$B$17 | D22: ='1. Matriz de Activos'!$C$17 | E22: ='1. Matriz de Activos'!$G$17 | F22: ='1. Matriz de Activos'!$E$17 | G22: ='1. Matriz de Activos'!$F$17 | H22: ='1. Matriz de Activos'!$T$17 | I22: =IF($H22>=4,"Sí","No") | J22: =IF($H22>=4,IFERROR(VLOOKUP($G22,AmenTabla,2,0),0),0) | K22: =COUNTIF('2. Valoración '!$C$6:$C$2261,$C22) | L22: =IF($I22="No","No requiere valoración",IF($K22=0,"FALTA POR COMPLETO — agregar "&$J22&" filas",IF($K22<$J22,"INCOMPLETO — faltan "&($J22-$K22)&" filas",IF($K22>$J22,"REVISAR — hay filas de más","Completo"))))
B23: =IF(AND(OR($C$6="(Todos los procesos)",$C$6='1. Matriz de Activos'!$G$18),OR($C$7="(Todos los tipos)",$C$7='1. Matriz de Activos'!$E$18),OR($C$8="(Todos los subtipos)",$C$8='1. Matriz de Activos'!$F$18)),"Sí","No") | C23: ='1. Matriz de Activos'!$B$18 | D23: ='1. Matriz de Activos'!$C$18 | E23: ='1. Matriz de Activos'!$G$18 | F23: ='1. Matriz de Activos'!$E$18 | G23: ='1. Matriz de Activos'!$F$18 | H23: ='1. Matriz de Activos'!$T$18 | I23: =IF($H23>=4,"Sí","No") | J23: =IF($H23>=4,IFERROR(VLOOKUP($G23,AmenTabla,2,0),0),0) | K23: =COUNTIF('2. Valoración '!$C$6:$C$2261,$C23) | L23: =IF($I23="No","No requiere valoración",IF($K23=0,"FALTA POR COMPLETO — agregar "&$J23&" filas",IF($K23<$J23,"INCOMPLETO — faltan "&($J23-$K23)&" filas",IF($K23>$J23,"REVISAR — hay filas de más","Completo"))))
B24: =IF(AND(OR($C$6="(Todos los procesos)",$C$6='1. Matriz de Activos'!$G$19),OR($C$7="(Todos los tipos)",$C$7='1. Matriz de Activos'!$E$19),OR($C$8="(Todos los subtipos)",$C$8='1. Matriz de Activos'!$F$19)),"Sí","No") | C24: ='1. Matriz de Activos'!$B$19 | D24: ='1. Matriz de Activos'!$C$19 | E24: ='1. Matriz de Activos'!$G$19 | F24: ='1. Matriz de Activos'!$E$19 | G24: ='1. Matriz de Activos'!$F$19 | H24: ='1. Matriz de Activos'!$T$19 | I24: =IF($H24>=4,"Sí","No") | J24: =IF($H24>=4,IFERROR(VLOOKUP($G24,AmenTabla,2,0),0),0) | K24: =COUNTIF('2. Valoración '!$C$6:$C$2261,$C24) | L24: =IF($I24="No","No requiere valoración",IF($K24=0,"FALTA POR COMPLETO — agregar "&$J24&" filas",IF($K24<$J24,"INCOMPLETO — faltan "&($J24-$K24)&" filas",IF($K24>$J24,"REVISAR — hay filas de más","Completo"))))
B25: =IF(AND(OR($C$6="(Todos los procesos)",$C$6='1. Matriz de Activos'!$G$20),OR($C$7="(Todos los tipos)",$C$7='1. Matriz de Activos'!$E$20),OR($C$8="(Todos los subtipos)",$C$8='1. Matriz de Activos'!$F$20)),"Sí","No") | C25: ='1. Matriz de Activos'!$B$20 | D25: ='1. Matriz de Activos'!$C$20 | E25: ='1. Matriz de Activos'!$G$20 | F25: ='1. Matriz de Activos'!$E$20 | G25: ='1. Matriz de Activos'!$F$20 | H25: ='1. Matriz de Activos'!$T$20 | I25: =IF($H25>=4,"Sí","No") | J25: =IF($H25>=4,IFERROR(VLOOKUP($G25,AmenTabla,2,0),0),0) | K25: =COUNTIF('2. Valoración '!$C$6:$C$2261,$C25) | L25: =IF($I25="No","No requiere valoración",IF($K25=0,"FALTA POR COMPLETO — agregar "&$J25&" filas",IF($K25<$J25,"INCOMPLETO — faltan "&($J25-$K25)&" filas",IF($K25>$J25,"REVISAR — hay filas de más","Completo"))))
B26: =IF(AND(OR($C$6="(Todos los procesos)",$C$6='1. Matriz de Activos'!$G$21),OR($C$7="(Todos los tipos)",$C$7='1. Matriz de Activos'!$E$21),OR($C$8="(Todos los subtipos)",$C$8='1. Matriz de Activos'!$F$21)),"Sí","No") | C26: ='1. Matriz de Activos'!$B$21 | D26: ='1. Matriz de Activos'!$C$21 | E26: ='1. Matriz de Activos'!$G$21 | F26: ='1. Matriz de Activos'!$E$21 | G26: ='1. Matriz de Activos'!$F$21 | H26: ='1. Matriz de Activos'!$T$21 | I26: =IF($H26>=4,"Sí","No") | J26: =IF($H26>=4,IFERROR(VLOOKUP($G26,AmenTabla,2,0),0),0) | K26: =COUNTIF('2. Valoración '!$C$6:$C$2261,$C26) | L26: =IF($I26="No","No requiere valoración",IF($K26=0,"FALTA POR COMPLETO — agregar "&$J26&" filas",IF($K26<$J26,"INCOMPLETO — faltan "&($J26-$K26)&" filas",IF($K26>$J26,"REVISAR — hay filas de más","Completo"))))
B27: =IF(AND(OR($C$6="(Todos los procesos)",$C$6='1. Matriz de Activos'!$G$22),OR($C$7="(Todos los tipos)",$C$7='1. Matriz de Activos'!$E$22),OR($C$8="(Todos los subtipos)",$C$8='1. Matriz de Activos'!$F$22)),"Sí","No") | C27: ='1. Matriz de Activos'!$B$22 | D27: ='1. Matriz de Activos'!$C$22 | E27: ='1. Matriz de Activos'!$G$22 | F27: ='1. Matriz de Activos'!$E$22 | G27: ='1. Matriz de Activos'!$F$22 | H27: ='1. Matriz de Activos'!$T$22 | I27: =IF($H27>=4,"Sí","No") | J27: =IF($H27>=4,IFERROR(VLOOKUP($G27,AmenTabla,2,0),0),0) | K27: =COUNTIF('2. Valoración '!$C$6:$C$2261,$C27) | L27: =IF($I27="No","No requiere valoración",IF($K27=0,"FALTA POR COMPLETO — agregar "&$J27&" filas",IF($K27<$J27,"INCOMPLETO — faltan "&($J27-$K27)&" filas",IF($K27>$J27,"REVISAR — hay filas de más","Completo"))))
B28: =IF(AND(OR($C$6="(Todos los procesos)",$C$6='1. Matriz de Activos'!$G$23),OR($C$7="(Todos los tipos)",$C$7='1. Matriz de Activos'!$E$23),OR($C$8="(Todos los subtipos)",$C$8='1. Matriz de Activos'!$F$23)),"Sí","No") | C28: ='1. Matriz de Activos'!$B$23 | D28: ='1. Matriz de Activos'!$C$23 | E28: ='1. Matriz de Activos'!$G$23 | F28: ='1. Matriz de Activos'!$E$23 | G28: ='1. Matriz de Activos'!$F$23 | H28: ='1. Matriz de Activos'!$T$23 | I28: =IF($H28>=4,"Sí","No") | J28: =IF($H28>=4,IFERROR(VLOOKUP($G28,AmenTabla,2,0),0),0) | K28: =COUNTIF('2. Valoración '!$C$6:$C$2261,$C28) | L28: =IF($I28="No","No requiere valoración",IF($K28=0,"FALTA POR COMPLETO — agregar "&$J28&" filas",IF($K28<$J28,"INCOMPLETO — faltan "&($J28-$K28)&" filas",IF($K28>$J28,"REVISAR — hay filas de más","Completo"))))
B29: =IF(AND(OR($C$6="(Todos los procesos)",$C$6='1. Matriz de Activos'!$G$24),OR($C$7="(Todos los tipos)",$C$7='1. Matriz de Activos'!$E$24),OR($C$8="(Todos los subtipos)",$C$8='1. Matriz de Activos'!$F$24)),"Sí","No") | C29: ='1. Matriz de Activos'!$B$24 | D29: ='1. Matriz de Activos'!$C$24 | E29: ='1. Matriz de Activos'!$G$24 | F29: ='1. Matriz de Activos'!$E$24 | G29: ='1. Matriz de Activos'!$F$24 | H29: ='1. Matriz de Activos'!$T$24 | I29: =IF($H29>=4,"Sí","No") | J29: =IF($H29>=4,IFERROR(VLOOKUP($G29,AmenTabla,2,0),0),0) | K29: =COUNTIF('2. Valoración '!$C$6:$C$2261,$C29) | L29: =IF($I29="No","No requiere valoración",IF($K29=0,"FALTA POR COMPLETO — agregar "&$J29&" filas",IF($K29<$J29,"INCOMPLETO — faltan "&($J29-$K29)&" filas",IF($K29>$J29,"REVISAR — hay filas de más","Completo"))))
B30: =IF(AND(OR($C$6="(Todos los procesos)",$C$6='1. Matriz de Activos'!$G$25),OR($C$7="(Todos los tipos)",$C$7='1. Matriz de Activos'!$E$25),OR($C$8="(Todos los subtipos)",$C$8='1. Matriz de Activos'!$F$25)),"Sí","No") | C30: ='1. Matriz de Activos'!$B$25 | D30: ='1. Matriz de Activos'!$C$25 | E30: ='1. Matriz de Activos'!$G$25 | F30: ='1. Matriz de Activos'!$E$25 | G30: ='1. Matriz de Activos'!$F$25 | H30: ='1. Matriz de Activos'!$T$25 | I30: =IF($H30>=4,"Sí","No") | J30: =IF($H30>=4,IFERROR(VLOOKUP($G30,AmenTabla,2,0),0),0) | K30: =COUNTIF('2. Valoración '!$C$6:$C$2261,$C30) | L30: =IF($I30="No","No requiere valoración",IF($K30=0,"FALTA POR COMPLETO — agregar "&$J30&" filas",IF($K30<$J30,"INCOMPLETO — faltan "&($J30-$K30)&" filas",IF($K30>$J30,"REVISAR — hay filas de más","Completo"))))
